Workbook

Sheet Navigation Key
A1: Page Navigation Key
A2: Page Type | B2: Page Color
A3: Information
A4: Parameters and Results
A5: Configuration - Traditional Onsite
A6: Configuration - Local Modular
A7: Configuration - Multi-Market Modular
A8: Sources and Calculations
A10: Cell Highlight Color
A11: Highlight Meaning | B11: Cell Color
A12: Modifiable Parameters

Sheet Model Information
A1: Supply Chain Configurations
A26: Summary of Model Calculations
A27: National Average (Traditional vs Local): 1. Itemized home construction to assembly process level 2. Used national average housing cost per square feet (source: NAHB) and average time (source: approximation from 2025 Capstone) for site built construction as benchmark 3. Estimated % of total cost for material vs labor (source: approximation) 4. Estimated % of total time per assembly process (source: 2025 Capstone and approximation) 5. Based on traditional, site-built as a benchmark, calculated cost and time % savings from local offsite construction (source: estimated % savings from public reports and approximation) 6. Compared cost results between traditional, site built and local, offsite housing based on national average Regional (Traditional vs Local): 7. Followed steps 2-5 at the regional level (Salt Lake City, UT and Los Angeles, CA) 8. Compare cost results between traditional, site built and local, off site housing for both markets separately Multi-Market : 9. Modular: multi-market factory in SLC shipping modules locally to SLC and distant to LA -- Use SLC material and labor costs with % savings from economies of scale (also account for larger facility = higher fixed costs). Production sq ft cost same for every module out of SLC facility, transportation cost per sq ft differs to each market --- SLC customers: Calculate transportation costs of modules to SLC local customers --- LA customers: Calculate transportation costs of modules to LA distant customers 10. Hybrid Scenario 1: multi-market hybrid factory in SLC shipping modules locally to SLC and shipping panels to local modular factory near LA which ships modules locally to LA customers -- Determine assembly processes to be done in hybrid SLC factory. Use SLC material and labor costs with % savings from economies of scale of shared processes (also account for larger facility = higher fixed costs). Production sq ft cost differ for modules, transportation cost per sq ft differs for each market --- SLC customers: Calculate transportation costs of modules to SLC local customers --- LA customers: Calculate transportation cost of panels from SLC hybrid facility to LA local modular facility. Use LA material and labor costs for localized processes. Calculate transportation cost of shipping modules from LA local modular facility to local LA customers 11. Hybrid Scenario 2: multi-market hybrid factory in SLC shipping panels to local modular factory in SLC which ships modules locally to SLC customers and shipping panels to local modular factory near LA which ships modules locally to LA customers -- Determine assembly processes to be done in hybrid SLC factory. Use SLC material and labor costs with % savings from economies of scale of shared processes (also account for larger facility = higher fixed costs). Production sq ft cost different for modules, transportation cost per sq ft differs to each market --- SLC customers: Calculate transportation cost of panels from SLC hybrid facility to SLC local modular facility. Use SLC material and labor costs for localized processes. Calculate transportation cost of shipping modules from SLC local modular facility to local customers --- LA customers: Calculate transportation cost of panels from SLC hybrid facility to LA local modular facility. Use LA material and labor costs for localized processes. Calculate transportation cost of shipping modules from LA local modular facility to local customers 12. Compare cost results between the three different multi-market scenarios

Sheet Overall Results
A1: Modular
A2: Manufacturing Strategy | B2: Market Location | C2: Construction Cost | D2: Other Costs | E2: Fixed Costs | F2: Profit | G2: Total Selling Price | H2: Profit % | I2: Construction Cost Savings % | K2: Check | M2: Unit of measure* | N2: Notes
A3: Site Built | B3: Salt Lake City | C3: ='SLC - Site Built'!B34 -> 150 | D3: ='SLC - Site Built'!B35 -> 57.763623 | E3: 0 | F3: ='SLC - Site Built'!B36 -> 25.683945 | G3: ='SLC - Site Built'!B37 -> 233.44757 | H3: =F3/G3 -> 0.11002019 | I3: 0 | K3: =F3-(G3-SUM(C3:E3)) -> 0 | M3: ='Parameter Adjustment'!Z2 -> Square foot | N3: *Go to parameter adjustment page to move
A4: Local | B4: Salt Lake City | C4: ='SLC - Local'!B32 -> 139.595 | D4: ='SLC - Local'!B33 -> 57.763623 | E4: ='SLC - Local'!B34 -> 19.152 | F4: ='SLC - Local'!B35 -> 16.936945 | G4: ='SLC - Local'!B36 -> 233.44757 | H4: =F4/G4 -> 0.07255139 | I4: =(C4-$C$3)/$C$3 -> -0.069366667 | K4: =F4-(G4-SUM(C4:E4)) -> -2.8421709e-14
A5: Multi-Market Modular | B5: Salt Lake City | C5: ='Multi-Market Modular'!B34 -> 128.57 | D5: ='Multi-Market Modular'!B35 -> 57.763623 | E5: ='Multi-Market Modular'!B36 -> 19.152 | F5: ='Multi-Market Modular'!B37 -> 27.961945 | G5: ='Multi-Market Modular'!B38 -> 233.44757 | H5: =F5/G5 -> 0.11977827 | I5: =(C5-$C$3)/$C$3 -> -0.14286667 | K5: =F5-(G5-SUM(C5:E5)) -> -2.8421709e-14
A6: Site Built | B6: Los Angeles | C6: ='LA - Site Built'!B34 -> 320 | D6: ='LA - Site Built'!B35 -> 123.22906 | E6: 0 | F6: ='LA - Site Built'!B36 -> 54.792417 | G6: ='LA - Site Built'!B37 -> 498.02148 | H6: =F6/G6 -> 0.11002019 | K6: =F6-(G6-SUM(C6:E6)) -> 0
A7: Local | B7: Los Angeles | C7: ='LA - Local'!B34 -> 285.676 | D7: ='LA - Local'!B35 -> 123.22906 | E7: ='LA - Local'!B36 -> 32.048 | F7: ='LA - Local'!B37 -> 57.068417 | G7: ='LA - Local'!B38 -> 498.02148 | H7: =F7/G7 -> 0.11459027 | I7: =(C7-$C$6)/$C$6 -> -0.1072625 | K7: =F7-(G7-SUM(C7:E7)) -> 0
A8: Multi-Market Modular | B8: Los Angeles | C8: ='Multi-Market Modular'!C34 -> 168.9525 | D8: ='Multi-Market Modular'!C35 -> 123.22906 | E8: ='Multi-Market Modular'!C36 -> 19.152 | F8: ='Multi-Market Modular'!C37 -> 186.68792 | G8: ='Multi-Market Modular'!C38 -> 498.02148 | H8: =F8/G8 -> 0.37485917 | I8: =(C8-$C$6)/$C$6 -> -0.47202344 | K8: =F8-(G8-SUM(C8:E8)) -> 0
A10: Hybrid
A11: Manufacturing Strategy | B11: Market Location | C11: Construction Cost | D11: Other Costs | E11: Fixed Costs | F11: Profit | G11: Total Selling Price | H11: Profit % | I11: Construction Cost Savings %
A12: Site Built | B12: Salt Lake City | C12: ='SLC - Site Built'!B34 -> 150 | D12: ='SLC - Site Built'!B35 -> 57.763623 | E12: 0 | F12: ='SLC - Site Built'!B36 -> 25.683945 | G12: ='SLC - Site Built'!B37 -> 233.44757 | H12: =F12/G12 -> 0.11002019 | I12: 0 | K12: =F12-(G12-SUM(C12:E12)) -> 0
A13: Multi-Market Hybrid 1 | B13: Salt Lake City | C13: ='Multi-Market Hybrid 1'!B34 -> 131.045 | D13: ='Multi-Market Hybrid 1'!B35 -> 57.763623 | E13: ='Multi-Market Hybrid 1'!B36 -> 38.304 | F13: ='Multi-Market Hybrid 1'!B37 -> 6.3349455 | G13: ='Multi-Market Hybrid 1'!B38 -> 233.44757 | H13: =F13/G13 -> 0.027136481 | I13: =(C13-$C$12)/$C$12 -> -0.12636667 | K13: =F13-(G13-SUM(C13:E13)) -> -1.4210855e-14
A14: Multi-Market Hybrid 2 | B14: Salt Lake City | C14: ='Multi-Market Hybrid 2'!B34 -> 133.67 | D14: ='Multi-Market Hybrid 2'!B35 -> 57.763623 | E14: ='Multi-Market Hybrid 2'!B36 -> 28.728 | F14: ='Multi-Market Hybrid 2'!B37 -> 13.285945 | G14: ='Multi-Market Hybrid 2'!B38 -> 233.44757 | H14: =F14/G14 -> 0.056911903 | I14: =(C14-$C$12)/$C$12 -> -0.10886667 | K14: =F14-(G14-SUM(C14:E14)) -> 2.1316282e-14
A15: Site Built | B15: Los Angeles | C15: ='LA - Site Built'!B34 -> 320 | D15: ='LA - Site Built'!B35 -> 123.22906 | E15: 0 | F15: ='LA - Site Built'!B36 -> 54.792417 | G15: ='LA - Site Built'!B37 -> 498.02148 | H15: =F15/G15 -> 0.11002019 | I15: 0 | K15: =F15-(G15-SUM(C15:E15)) -> 0
A16: Multi-Market Hybrid 1 | B16: Los Angeles | C16: ='Multi-Market Hybrid 1'!C34 -> 219.308 | D16: ='Multi-Market Hybrid 1'!C35 -> 123.22906 | E16: ='Multi-Market Hybrid 1'!C36 -> 51.2 | F16: ='Multi-Market Hybrid 1'!C37 -> 104.28442 | G16: ='Multi-Market Hybrid 1'!C38 -> 498.02148 | H16: =F16/G16 -> 0.20939743 | I16: =(C16-$C$15)/$C$15 -> -0.3146625 | K16: =F16-(G16-SUM(C16:E16)) -> 0
A17: Multi-Market Hybrid 2 | B17: Los Angeles | C17: ='Multi-Market Hybrid 2'!C34 -> 219.308 | D17: ='Multi-Market Hybrid 2'!C35 -> 123.22906 | E17: ='Multi-Market Hybrid 2'!C36 -> 41.624 | F17: ='Multi-Market Hybrid 2'!C37 -> 113.86042 | G17: ='Multi-Market Hybrid 2'!C38 -> 498.02148 | H17: =F17/G17 -> 0.22862551 | I17: =(C17-$C$15)/$C$15 -> -0.3146625 | K17: =F17-(G17-SUM(C17:E17)) -> 0

Sheet Parameter Adjustment
A1: Site Built - Process Percentage Allocation | F1: Economies of Scale (Eos) Savings | L1: Notes | N1: =Z2 -> Square foot | P1: Site Built Time (days) | R1: Modular Transportation Costs | W1: On-site Installation Cost | Z1: Select Unit Of Measure | AB1: Cost per Sqft | AE1: Facility Fixed Costs
A2: Construction Process | B2: % Material Cost | C2: % Labor Cost | D2: % of Total Cost | E2: % of Total Time | F2: LOCAL % Cost Savings (Modular) | G2: LOCAL % Time Savings (Modular) | H2: MULTI-MARKET LOCAL % Cost Savings (Modular) | I2: MULTI-MARKET LOCAL % Time Savings (Modular) | J2: MULTI-MARKET CENTRAL % Cost Savings (Hybrid) | K2: MULTI-MARKET HYBRID % Time Savings (Hybrid) | L2: NAHB Category Reference (% of Total Cost) | P2: 210 | R2: Type | S2: Cost Per Mile | T2: Distance (miles) | U2: Inter-state Permit ($100/state) | W2: Sqft | X2: 1000 | Z2: Square foot | AB2: Market | AC2: Value | AE2: Facility Location | AF2: Configuration | AG2: 1-Yr Lease | AH2: Equipment | AI2: Total Fixed Costs per Year | AJ2: Modular Fixed Costs/Sqft | AK2: Panel Fixed Costs/Sqft
A3: Site Work | B3: 0.6 | C3: 0.4 | D3: 0.076 | E3: 0.10810811 | F3: 0 | G3: 1 | H3: 0 | I3: 1 | J3: 0 | K3: 1 | L3: NAHB (Site Work) | N3: NA Site Built Cost | R3: Local (SLC) | S3: 14 | T3: 50 | W3: $/Sqft | X3: 10 | AB3: Los Angeles | AC3: 320 | AE3: Los Angeles | AF3: Local | AG3: {=_xlfn.IFS(AND(AE3="Los Angeles",AF3="Local"),$AF$11*$AF$16,AND(AE3="Salt Lake City",AF3="Local"),$AF$11*$AF$17,AND(AE3="Salt Lake City",AF3=OR("Multi-Market Modular","Multi-Market Hybrid")),$AF$12*$AF$17)} -> 951500 | AH3: =IF(AF3="Local",$AF$29, $AF$30) -> 50000 | AI3: =AG3+AH3 -> 1001500 | AJ3: =$AI3/AG21 -> 32.048 | AK3: =$AI3/AH21 -> #DIV/0!
A4: Foundations | B4: 0.7 | C4: 0.3 | D4: 0.105 | E4: 0.10810811 | F4: 0 | G4: 1 | H4: 0 | I4: 1 | J4: 0 | K4: 1 | L4: NAHB (Foundations) | N4: =IF(Z2="1,000 square-foot home", AC5*1000, AC5) -> 161 | R4: Local (LA) | S4: 16 | T4: 50 | AB4: Salt Lake City | AC4: 150 | AE4: Salt Lake City | AF4: Local | AG4: {=_xlfn.IFS(AND(AE4="Los Angeles",AF4="Local"),$AF$11*$AF$16,AND(AE4="Salt Lake City",AF4="Local"),$AF$11*$AF$17,AND(AE4="Salt Lake City",AF4=OR("Multi-Market Modular","Multi-Market Hybrid")),$AF$12*$AF$17)} -> 548500 | AH4: =IF(AF4="Local",$AF$29, $AF$30) -> 50000 | AI4: =AG4+AH4 -> 598500 | AJ4: =$AI4/AG22 -> 19.152 | AK4: =$AI4/AH22 -> #DIV/0!
A5: Floor framing | B5: 0.6 | C5: 0.4 | D5: =16.6%/COUNTA($A$6:$A$13) -> 0.02075 | E5: 0.032432432 | F5: 0.1 | G5: 0.2 | H5: 0.15 | I5: 0.2 | J5: 0.2 | K5: 0.2 | L5: NAHB (Average 16.6%/7 all Framing, Trusses, Sheathing, Other) | R5: Distant (SLC-LA) | S5: =10+(T5/U5) -> 13.75 | T5: 750 | U5: =2*100 -> 200 | AB5: National Average | AC5: 161 | AE5: Salt Lake City | AF5: Multi-Market Modular | AG5: {=_xlfn.IFS(AND(AE5="Los Angeles",AF5="Local"),$AF$11*$AF$16,AND(AE5="Salt Lake City",AF5="Local"),$AF$11*$AF$17,AND(AE5="Salt Lake City",AF5="Multi-Market Modular"),$AF$12*$AF$17,AND(AE5="Salt Lake City",AF5="Multi-Market Hybrid"),$AF$12*$AF$17)} -> 1097000 | AH5: =IF(AF5="Local",$AF$29, $AF$30) -> 100000 | AI5: =AG5+AH5 -> 1197000 | AJ5: =$AI5/AG23 -> 19.152 | AK5: =$AI5/AH23 -> #DIV/0!
A6: Floor sheathing | B6: 0.6 | C6: 0.4 | D6: =16.6%/COUNTA($A$6:$A$13) -> 0.02075 | E6: 0.016216216 | F6: 0.1 | G6: 0.2 | H6: 0.15 | I6: 0.2 | J6: 0.2 | K6: 0.2 | AE6: Salt Lake City | AF6: Multi-Market Hybrid 1 | AG6: {=_xlfn.IFS(AND(AE6="Los Angeles",AF6="Local"),$AF$11*$AF$16,AND(AE6="Salt Lake City",AF6="Local"),$AF$11*$AF$17,AND(AE6="Salt Lake City",AF6="Multi-Market Modular"),$AF$12*$AF$17,AND(AE6="Salt Lake City",AF6="Multi-Market Hybrid 1"),$AF$12*$AF$17)} -> 1097000 | AH6: =IF(AF6="Local",$AF$29, $AF$30) -> 100000 | AI6: =AG6+AH6 -> 1197000 | AJ6: =$AI6/AG24 -> 38.304 | AK6: =$AI6/AH24 -> 19.152
A7: Interior Wall framing | B7: 0.6 | C7: 0.4 | D7: =16.6%/COUNTA($A$6:$A$13) -> 0.02075 | E7: 0.040540541 | F7: 0.1 | G7: 0.2 | H7: 0.15 | I7: 0.2 | J7: 0.2 | K7: 0.2 | N7: LA Site Built Cost | AE7: Salt Lake City | AF7: Multi-Market Hybrid 2 | AG7: {=_xlfn.IFS(AND(AE7="Los Angeles",AF7="Local"),$AF$11*$AF$16,AND(AE7="Salt Lake City",AF7="Local"),$AF$11*$AF$17,AND(AE7="Salt Lake City",AF7="Multi-Market Modular"),$AF$12*$AF$17,AND(AE7="Salt Lake City",AF7="Multi-Market Hybrid 1"),$AF$12*$AF$17,AND(AE7="Salt Lake City",AF7="Multi-Market Hybrid 2"),$AF$12*$AF$17)} -> 1097000 | AH7: =IF(AF7="Local",$AF$29, $AF$30) -> 100000 | AI7: =AG7+AH7 -> 1197000 | AJ7: =$AI7/AG25 -> #DIV/0! | AK7: =$AI7/AH25 -> 9.576
A8: Interior Wall sheathing | B8: 0.6 | C8: 0.4 | D8: =16.6%/COUNTA($A$6:$A$13) -> 0.02075 | E8: 0.016216216 | F8: 0.1 | G8: 0.2 | H8: 0.15 | I8: 0.2 | J8: 0.2 | K8: 0.2 | N8: =IF(Z2="1,000 square-foot home", AC3*1000, AC3) -> 320 | R8: Components + 2D Panels Transportation Costs
A9: Exterior Walls framing | B9: 0.6 | C9: 0.4 | D9: =16.6%/COUNTA($A$6:$A$13) -> 0.02075 | E9: 0.091891892 | F9: 0.1 | G9: 0.2 | H9: 0.15 | I9: 0.2 | J9: 0.2 | K9: 0.2 | R9: Type | S9: Cost Per Mile | T9: Distance (miles) | AE9: Configuration Sizes
A10: Exterior Wall sheathing | B10: 0.6 | C10: 0.4 | D10: =16.6%/COUNTA($A$6:$A$13) -> 0.02075 | E10: 0.027027027 | F10: 0.1 | G10: 0.2 | H10: 0.15 | I10: 0.2 | J10: 0.2 | K10: 0.2 | R10: Local (SLC) | S10: 3 | T10: 50 | AE10: Configuration | AF10: Size (sqft) | AG10: Note
A11: Roof framing | B11: 0.6 | C11: 0.4 | D11: =16.6%/COUNTA($A$6:$A$13) -> 0.02075 | E11: 0.032432432 | F11: 0.1 | G11: 0.2 | H11: 0.15 | I11: 0.2 | J11: 0.2 | K11: 0.2 | N11: SLC Site Built Cost | R11: Local (LA) | S11: 4 | T11: 50 | AE11: Local | AF11: 50000 | AG11: Industry Company Reports 18-50k sqft
A12: Roof sheathing and waterproofing | B12: 0.6 | C12: 0.4 | D12: =16.6%/COUNTA($A$6:$A$13) -> 0.02075 | E12: 0.027027027 | F12: 0.1 | G12: 0.2 | H12: 0.15 | I12: 0.2 | J12: 0.2 | K12: 0.2 | N12: =IF(Z2="1,000 square-foot home", AC4*1000, AC4) -> 150 | R12: Distant (SLC-LA) | S12: 4 | T12: 750 | AE12: Multi-Market | AF12: 100000 | AG12: Industry Company Reports 110k sqft
A13: Mechanical Rough In | B13: 0.3 | C13: 0.7 | D13: 0.063 | E13: 0.045945946 | F13: 0.1 | G13: 0.2 | H13: 0.15 | I13: 0.2 | J13: 0.2 | K13: 0.2 | L13: NAHB (Major Systems Rough-ins Plumbing)
A14: Electrical Rough In | B14: 0.3 | C14: 0.7 | D14: 0.064 | E14: 0.02972973 | F14: 0.1 | G14: 0.2 | H14: 0.15 | I14: 0.2 | J14: 0.2 | K14: 0.2 | L14: NAHB (Major Systems Rough-ins Electrical) | AE14: Lease Costs
A15: Plumbing Rough In | B15: 0.3 | C15: 0.7 | D15: 0.063 | E15: 0.043243243 | F15: 0.1 | G15: 0.2 | H15: 0.15 | I15: 0.2 | J15: 0.2 | K15: 0.2 | L15: NAHB (Major Systems Rough-ins HVAC) | AE15: Facility Location | AF15: $/Sqft/Yr | AG15: Source
A16: Insulation | B16: 0.6 | C16: 0.4 | D16: 0.016 | E16: 0.032432432 | F16: 0.1 | G16: 0.2 | H16: 0.15 | I16: 0.2 | J16: 0.2 | K16: 0.2 | L16: NAHB (Interior Finishes Insulation) | AE16: Los Angeles | AF16: 19.03 | AG16: Property Shark
A17: Drywall | B17: 0.6 | C17: 0.4 | D17: 0.033 | E17: 0.021621622 | F17: 0.1 | G17: 0.2 | H17: 0.15 | I17: 0.2 | J17: 0.2 | K17: 0.2 | L17: NAHB (Interior Finishes Drywall) | AE17: Salt Lake City | AF17: 10.97 | AG17: Property Shark
A18: Mechanical Finishing | B18: 0.6 | C18: 0.4 | D18: 0.01 | E18: 0.045945946 | F18: 0.1 | G18: 0.2 | H18: 0.15 | I18: 0.2 | J18: 0.2 | K18: 0.2 | L18: NAHB (Interior Finishes Fireplace, Other)
A19: Electrical Finishing | B19: 0.6 | C19: 0.4 | D19: 0.031 | E19: 0.045945946 | F19: 0.1 | G19: 0.2 | H19: 0.15 | I19: 0.2 | J19: 0.2 | K19: 0.2 | L19: NAHB (Interior Finishes Appliances, Lighting) | AE19: Throughput
A20: Plumbing Finishing | B20: 0.6 | C20: 0.4 | D20: 0.019 | E20: 0.045945946 | F20: 0.1 | G20: 0.2 | H20: 0.15 | I20: 0.2 | J20: 0.2 | K20: 0.2 | L20: NAHB (Interior Finishes Plumbing Fixtures) | AE20: Facility Location | AF20: Configuration | AG20: Modular Throughput (Sqft) | AH20: Panel Throughput (Sqft) | AI20: Note
A21: Carpentry | B21: 0.3 | C21: 0.7 | D21: =(3+4.5)/100 -> 0.075 | E21: 0.043243243 | F21: 0.1 | G21: 0.2 | H21: 0.15 | I21: 0.2 | J21: 0.2 | K21: 0.2 | L21: NAHB (Interior Finishes Trims, Doors, and Mirrors, Cabinets, Countertops) | AE21: Los Angeles | AF21: Local | AG21: =AVERAGE(500,750)*50 -> 31250 | AI21: Industry Company Reports 500-750 sqft per week. Assume 50 working weeks
A22: Floor Finishing | B22: 0.6 | C22: 0.4 | D22: 0.036 | E22: 0.016216216 | F22: 0.1 | G22: 0.2 | H22: 0.15 | I22: 0.2 | J22: 0.2 | K22: 0.2 | L22: NAHB (Interior Finishes Flooring) | AE22: Salt Lake City | AF22: Local | AG22: =AVERAGE(500,750)*50 -> 31250
A23: Painting | B23: 0.3 | C23: 0.7 | D23: 0.026 | E23: 0.016216216 | F23: 0.1 | G23: 0.2 | H23: 0.15 | I23: 0.2 | J23: 0.2 | K23: 0.2 | L23: NAHB (Interior Finishes Painting) | AE23: Salt Lake City | AF23: Multi-Market Modular | AG23: =AG22*(AF12/AF11) -> 62500 | AI23: Assume double Local config. 50% SLC and 50% LA
A24: Exterior Wall Finishing | B24: 0.6 | C24: 0.4 | D24: =(5.7+3.7)/100 -> 0.094 | E24: 0.027027027 | F24: 0.1 | G24: 0.2 | H24: 0.15 | I24: 0.2 | J24: 0.2 | K24: 0.2 | L24: NAHB (Exterior Finsihes Wall, Windows and Doors) | AE24: Salt Lake City | AF24: Multi-Market Hybrid 1 | AG24: =(AG23/2) -> 31250 | AH24: =(AG23/2*2) -> 62500 | AI24: Assume 50% modular, 50% panel with panels being 2x faster
A25: Exterior Roof Finishing | B25: 0.6 | C25: 0.4 | D25: 0.039 | E25: 0.027027027 | F25: 0.1 | G25: 0.2 | H25: 0.15 | I25: 0.2 | J25: 0.2 | K25: 0.2 | L25: NAHB (Exterior Finsihes Roofing) | AE25: Salt Lake City | AF25: Multi-Market Hybrid 2 | AH25: =(AG23/2*2)+(AG23/2*2) -> 125000 | AI25: Assume 100% panel, 2x faster than modular
A26: Transportation
A27: Assembly | AE27: Equipment Fixed Costs (Assume Same Regardless of Location)
A28: All Inspections | C28: 1 | D28: 0.084 | E28: 0.059459459 | F28: 0.8 | G28: 0.8 | H28: 0.8 | I28: 0.8 | J28: 0.8 | K28: 0.8 | L28: NAHB (Final Steps and Other) | AE28: Configuration | AF28: Total Equip Costs | AG28: Source
A29: Total | D29: =SUM(D3:D28) -> 1 | E29: =SUM(E3:E28) -> 1 | AE29: Local | AF29: 50000 | AG29: Estimate
AE30: Multi-Market | AF30: 100000 | AG30: Estimate
B33: Modifiable Parameters
A36: Hourly Labor Cost (facility location model)
A37: Construction Process | B37: CA - Los Angeles | C37: UT - Salt Lake City | D37: National Average | E37: BLS - OEWS Category Reference
A38: Site Work | B38: =_xlfn.XLOOKUP("*" & $A38 & "*",'OEWS - California May 2024'!$A:$A,'OEWS - California May 2024'!$E:$E, "Not Found", 2) -> 31.8 | C38: =_xlfn.XLOOKUP("*" & $A38 & "*",'OEWS - Utah May 2024'!$A:$A,'OEWS - Utah May 2024'!$E:$E, "Not Found", 2) -> 22.96 | D38: =_xlfn.XLOOKUP("*" & $A38 & "*",'OEWS - National May 2024'!$A:$A,'OEWS - National May 2024'!$E:$E, "Not Found", 2) -> 24.64 | E38: =_xlfn.XLOOKUP("*" & $A38 & "*",'OEWS - National May 2024'!$A:$A,'OEWS - National May 2024'!$B:$B, "Not Found", 2) -> Construction Laborers (47-2061)
A39: Foundations | B39: =_xlfn.XLOOKUP("*" & $A39 & "*",'OEWS - California May 2024'!$A:$A,'OEWS - California May 2024'!$E:$E, "Not Found", 2) -> 31.8 | C39: =_xlfn.XLOOKUP("*" & $A39 & "*",'OEWS - Utah May 2024'!$A:$A,'OEWS - Utah May 2024'!$E:$E, "Not Found", 2) -> 22.96 | D39: =_xlfn.XLOOKUP("*" & $A39 & "*",'OEWS - National May 2024'!$A:$A,'OEWS - National May 2024'!$E:$E, "Not Found", 2) -> 24.64 | E39: =_xlfn.XLOOKUP("*" & $A39 & "*",'OEWS - National May 2024'!$A:$A,'OEWS - National May 2024'!$B:$B, "Not Found", 2) -> Construction Laborers (47-2061)
A40: Floor framing | B40: =_xlfn.XLOOKUP("*" & $A40 & "*",'OEWS - California May 2024'!$A:$A,'OEWS - California May 2024'!$E:$E, "Not Found", 2) -> 34.68 | C40: =_xlfn.XLOOKUP("*" & $A40 & "*",'OEWS - Utah May 2024'!$A:$A,'OEWS - Utah May 2024'!$E:$E, "Not Found", 2) -> 22.81 | D40: =_xlfn.XLOOKUP("*" & $A40 & "*",'OEWS - National May 2024'!$A:$A,'OEWS - National May 2024'!$E:$E, "Not Found", 2) -> 29.11 | E40: =_xlfn.XLOOKUP("*" & $A40 & "*",'OEWS - National May 2024'!$A:$A,'OEWS - National May 2024'!$B:$B, "Not Found", 2) -> Floor Layers, Except Carpet, Wood, and Hard Tiles (47-2042)
A41: Floor sheathing | B41: =_xlfn.XLOOKUP("*" & $A41 & "*",'OEWS - California May 2024'!$A:$A,'OEWS - California May 2024'!$E:$E, "Not Found", 2) -> 34.68 | C41: =_xlfn.XLOOKUP("*" & $A41 & "*",'OEWS - Utah May 2024'!$A:$A,'OEWS - Utah May 2024'!$E:$E, "Not Found", 2) -> 22.81 | D41: =_xlfn.XLOOKUP("*" & $A41 & "*",'OEWS - National May 2024'!$A:$A,'OEWS - National May 2024'!$E:$E, "Not Found", 2) -> 29.11 | E41: =_xlfn.XLOOKUP("*" & $A41 & "*",'OEWS - National May 2024'!$A:$A,'OEWS - National May 2024'!$B:$B, "Not Found", 2) -> Floor Layers, Except Carpet, Wood, and Hard Tiles (47-2042)
A42: Interior Wall framing | B42: =_xlfn.XLOOKUP("*" & $A42 & "*",'OEWS - California May 2024'!$A:$A,'OEWS - California May 2024'!$E:$E, "Not Found", 2) -> 37.35 | C42: =_xlfn.XLOOKUP("*" & $A42 & "*",'OEWS - Utah May 2024'!$A:$A,'OEWS - Utah May 2024'!$E:$E, "Not Found", 2) -> 26.26 | D42: =_xlfn.XLOOKUP("*" & $A42 & "*",'OEWS - National May 2024'!$A:$A,'OEWS - National May 2024'!$E:$E, "Not Found", 2) -> 30.79 | E42: =_xlfn.XLOOKUP("*" & $A42 & "*",'OEWS - National May 2024'!$A:$A,'OEWS - National May 2024'!$B:$B, "Not Found", 2) -> Carpenters (47-2031)
A43: Interior Wall sheathing | B43: =_xlfn.XLOOKUP("*" & $A43 & "*",'OEWS - California May 2024'!$A:$A,'OEWS - California May 2024'!$E:$E, "Not Found", 2) -> 37.35 | C43: =_xlfn.XLOOKUP("*" & $A43 & "*",'OEWS - Utah May 2024'!$A:$A,'OEWS - Utah May 2024'!$E:$E, "Not Found", 2) -> 26.26 | D43: =_xlfn.XLOOKUP("*" & $A43 & "*",'OEWS - National May 2024'!$A:$A,'OEWS - National May 2024'!$E:$E, "Not Found", 2) -> 30.79 | E43: =_xlfn.XLOOKUP("*" & $A43 & "*",'OEWS - National May 2024'!$A:$A,'OEWS - National May 2024'!$B:$B, "Not Found", 2) -> Carpenters (47-2031)
A44: Exterior Walls framing | B44: =_xlfn.XLOOKUP("*" & $A44 & "*",'OEWS - California May 2024'!$A:$A,'OEWS - California May 2024'!$E:$E, "Not Found", 2) -> 37.35 | C44: =_xlfn.XLOOKUP("*" & $A44 & "*",'OEWS - Utah May 2024'!$A:$A,'OEWS - Utah May 2024'!$E:$E, "Not Found", 2) -> 26.26 | D44: =_xlfn.XLOOKUP("*" & $A44 & "*",'OEWS - National May 2024'!$A:$A,'OEWS - National May 2024'!$E:$E, "Not Found", 2) -> 30.79 | E44: =_xlfn.XLOOKUP("*" & $A44 & "*",'OEWS - National May 2024'!$A:$A,'OEWS - National May 2024'!$B:$B, "Not Found", 2) -> Carpenters (47-2031)
...

Sheet OEWS - National May 2024
B1: Multiple occupations for one geographical area
B3: Area: National
B4: Period: May 2024
A6: Capstone Construction Process Cat. | B6: Occupation (SOC code) | C6: Employment (1) | D6: Employment percent relative standard error (3) | E6: Hourly mean wage | F6: Annual mean wage (2) | G6: Wage percent relative standard error (3) | H6: Hourly 10th percentile wage | I6: Hourly 25th percentile wage | J6: Hourly median wage | K6: Hourly 75th percentile wage | L6: Hourly 90th percentile wage | M6: Annual 10th percentile wage (2) | N6: Annual 25th percentile wage (2) | O6: Annual median wage (2) | P6: Annual 75th percentile wage (2) | Q6: Annual 90th percentile wage (2)
B7: Construction and Extraction Occupations (47-0000) | C7: 6361720 | D7: 0.2 | E7: 30.73 | F7: 63920 | G7: 0.30000001 | H7: 18 | I7: 22.13 | J7: 28.06 | K7: 36.93 | L7: 48.28 | M7: 37440 | N7: 46030 | O7: 58360 | P7: 76820 | Q7: 100430
B8: First-Line Supervisors of Construction Trades and Extraction Workers (47-1011) | C8: 806080 | D8: 0.60000002 | E8: 40.62 | F8: 84500 | G8: 0.40000001 | H8: 24.66 | I8: 30 | J8: 37.83 | K8: 48.17 | L8: 60.91 | M8: 51290 | N8: 62400 | O8: 78690 | P8: 100200 | Q8: 126690
B9: Construction Trades Workers (47-2000) | C9: 4691890 | D9: 0.30000001 | E9: 29.6 | F9: 61560 | G9: 0.30000001 | H9: 17.91 | I9: 21.9 | J9: 27.16 | K9: 35.47 | L9: 46.47 | M9: 37260 | N9: 45560 | O9: 56490 | P9: 73780 | Q9: 96650
B10: Boilermakers (47-2011) | C10: 10170 | D10: 5.8000002 | E10: 36.97 | F10: 76900 | G10: 1.6 | H10: 23.26 | I10: 29.92 | J10: 35.26 | K10: 44.96 | L10: 51.73 | M10: 48390 | N10: 62230 | O10: 73340 | P10: 93520 | Q10: 107600
B11: Brickmasons, Blockmasons, and Stonemasons (47-2020) | C11: 62260 | D11: 2.9000001 | E11: 30.89 | F11: 64240 | G11: 1 | H11: 19.39 | I11: 23.41 | J11: 28.93 | K11: 36.7 | L11: 45.28 | M11: 40330 | N11: 48690 | O11: 60180 | P11: 76340 | Q11: 94190
B12: Brickmasons and Blockmasons (47-2021) | C12: 53520 | D12: 3.0999999 | E12: 31.44 | F12: 65390 | G12: 1 | H12: 19.87 | I12: 23.76 | J12: 29.23 | K12: 37.16 | L12: 45.94 | M12: 41330 | N12: 49430 | O12: 60800 | P12: 77290 | Q12: 95560
B13: Stonemasons (47-2022) | C13: 8750 | D13: 6.6999998 | E13: 27.51 | F13: 57220 | G13: 2 | H13: 17.99 | I13: 21.55 | J13: 25 | K13: 30.83 | L13: 40 | M13: 37420 | N13: 44820 | O13: 51990 | P13: 64120 | Q13: 83200
A14: Interior Wall framing Interior Wall sheathing Exterior Walls framing Exterior Wall sheathing Carpentry | B14: Carpenters (47-2031) | C14: 697740 | D14: 1.2 | E14: 30.79 | F14: 64040 | G14: 0.5 | H14: 18.64 | I14: 22.86 | J14: 28.51 | K14: 36.36 | L14: 47.3 | M14: 38760 | N14: 47550 | O14: 59310 | P14: 75620 | Q14: 98370
B15: Carpet, Floor, and Tile Installers and Finishers (47-2040) | C15: 82710 | D15: 2.4000001 | E15: 27.8 | F15: 57830 | G15: 1 | H15: 17.24 | I15: 20.92 | J15: 25 | K15: 31.64 | L15: 41.49 | M15: 35850 | N15: 43520 | O15: 52000 | P15: 65810 | Q15: 86290
B16: Carpet Installers (47-2041) | C16: 14980 | D16: 6.1999998 | E16: 26.85 | F16: 55860 | G16: 2.0999999 | H16: 15.78 | I16: 18.82 | J16: 23.97 | K16: 31.51 | L16: 40 | M16: 32830 | N16: 39140 | O16: 49850 | P16: 65530 | Q16: 83200
A17: Floor framing Floor sheathing | B17: Floor Layers, Except Carpet, Wood, and Hard Tiles (47-2042) | C17: 24850 | D17: 5.1999998 | E17: 29.11 | F17: 60550 | G17: 1.7 | H17: 17.88 | I17: 21.52 | J17: 26.13 | K17: 34.8 | L17: 46.72 | M17: 37190 | N17: 44760 | O17: 54340 | P17: 72390 | Q17: 97180
B18: Floor Sanders and Finishers (47-2043) | C18: 4140 | D18: 12.1 | E18: 24.46 | F18: 50880 | G18: 2.3 | H18: 17.21 | I18: 19.87 | J18: 23.63 | K18: 27.99 | L18: 31.98 | M18: 35790 | N18: 41320 | O18: 49150 | P18: 58230 | Q18: 66510
A19: Floor Finishing | B19: Tile and Stone Setters (47-2044) | C19: 38740 | D19: 4.0999999 | E19: 27.69 | F19: 57590 | G19: 1.5 | H19: 17.38 | I19: 21.41 | J19: 25.11 | K19: 31.24 | L19: 39.89 | M19: 36140 | N19: 44540 | O19: 52240 | P19: 64980 | Q19: 82960
B20: Cement Masons, Concrete Finishers, and Terrazzo Workers (47-2050) | C20: 206680 | D20: 1.6 | E20: 28.55 | F20: 59380 | G20: 0.60000002 | H20: 18.41 | I20: 22.13 | J20: 26.3 | K20: 31.68 | L20: 42.19 | M20: 38290 | N20: 46020 | O20: 54700 | P20: 65890 | Q20: 87760
B21: Cement Masons and Concrete Finishers (47-2051) | C21: 205230 | D21: 1.6 | E21: 28.54 | F21: 59360 | G21: 0.60000002 | H21: 18.41 | I21: 22.13 | J21: 26.28 | K21: 31.66 | L21: 42.13 | M21: 38290 | N21: 46020 | O21: 54660 | P21: 65840 | Q21: 87620
B22: Terrazzo Workers and Finishers (47-2053) | C22: 1450 | D22: 20.1 | E22: 29.97 | F22: 62330 | G22: 6.5 | H22: 18.92 | I22: 22.57 | J22: 27.53 | K22: 35.33 | L22: 50.24 | M22: 39360 | N22: 46940 | O22: 57260 | P22: 73490 | Q22: 104510
A23: Site Work Foundations Assembly | B23: Construction Laborers (47-2061) | C23: 1057660 | D23: 0.69999999 | E23: 24.64 | F23: 51260 | G23: 0.40000001 | H23: 16.44 | I23: 18.32 | J23: 22.47 | K23: 28.32 | L23: 37.28 | M23: 34200 | N23: 38100 | O23: 46730 | P23: 58910 | Q23: 77530
B24: Construction Equipment Operators (47-2070) | C24: 518000 | D24: 0.69999999 | E24: 31.1 | F24: 64680 | G24: 0.40000001 | H24: 19.16 | I24: 22.88 | J24: 28.04 | K24: 36.24 | L24: 48.04 | M24: 39850 | N24: 47590 | O24: 58320 | P24: 75370 | Q24: 99930
B25: Paving, Surfacing, and Tamping Equipment Operators (47-2071) | C25: 45680 | D25: 3.4000001 | E25: 28.2 | F25: 58660 | G25: 1.3 | H25: 18.29 | I25: 21.51 | J25: 24.83 | K25: 31.76 | L25: 43.32 | M25: 38030 | N25: 44740 | O25: 51650 | P25: 66060 | Q25: 90110
B26: Pile Driver Operators (47-2072) | C26: 3040 | D26: 9.8999996 | E26: 37.98 | F26: 79000 | G26: 3.0999999 | H26: 22.45 | I26: 26.32 | J26: 33.9 | K26: 49.98 | L26: 58.65 | M26: 46690 | N26: 54750 | O26: 70510 | P26: 103960 | Q26: 121990
B27: Operating Engineers and Other Construction Equipment Operators (47-2073) | C27: 469270 | D27: 0.80000001 | E27: 31.34 | F27: 65180 | G27: 0.40000001 | H27: 19.27 | I27: 22.97 | J27: 28.23 | K27: 36.42 | L27: 48.41 | M27: 40080 | N27: 47780 | O27: 58710 | P27: 75750 | Q27: 100690
B28: Drywall Installers, Ceiling Tile Installers, and Tapers (47-2080) | C28: 95400 | D28: 2.2 | E28: 30.68 | F28: 63800 | G28: 1 | H28: 18.35 | I28: 22.63 | J28: 28.27 | K28: 35.78 | L28: 49.48 | M28: 38160 | N28: 47070 | O28: 58800 | P28: 74410 | Q28: 102920
A29: Drywall | B29: Drywall and Ceiling Tile Installers (47-2081) | C29: 82900 | D29: 2.2 | E29: 30.2 | F29: 62810 | G29: 1 | H29: 18.18 | I29: 22.54 | J29: 27.95 | K29: 34.93 | L29: 48.74 | M29: 37810 | N29: 46880 | O29: 58140 | P29: 72660 | Q29: 101380
B30: Tapers (47-2082) | C30: 12500 | D30: 7.5999999 | E30: 33.84 | F30: 70390 | G30: 2 | H30: 20.89 | I30: 24.42 | J30: 31.11 | K30: 39.9 | L30: 51.04 | M30: 43450 | N30: 50780 | O30: 64700 | P30: 82990 | Q30: 106160
A31: Electrical Rough in Electrical Finishing | B31: Electricians (47-2111) | C31: 742580 | D31: 0.69999999 | E31: 33.47 | F31: 69630 | G31: 0.5 | H31: 18.96 | I31: 23.47 | J31: 29.98 | K31: 39.29 | L31: 50.98 | M31: 39430 | N31: 48820 | O31: 62350 | P31: 81730 | Q31: 106030
B32: Glaziers (47-2121) | C32: 57000 | D32: 3.0999999 | E32: 28.97 | F32: 60260 | G32: 1.8 | H32: 18.13 | I32: 21.89 | J32: 26.65 | K32: 32.84 | L32: 47.49 | M32: 37710 | N32: 45530 | O32: 55440 | P32: 68300 | Q32: 98780
B33: Insulation Workers (47-2130) | C33: 64250 | D33: 2.9000001 | E33: 27.63 | F33: 57470 | G33: 1.3 | H33: 17.76 | I33: 21.28 | J33: 24.39 | K33: 30.67 | L33: 40 | M33: 36950 | N33: 44260 | O33: 50730 | P33: 63800 | Q33: 83200
A34: Insulation | B34: Insulation Workers, Floor, Ceiling, and Wall (47-2131) | C34: 38610 | D34: 3.5 | E34: 25.69 | F34: 53440 | G34: 1.5 | H34: 17.28 | I34: 19.36 | J34: 23.41 | K34: 29.05 | L34: 37.1 | M34: 35950 | N34: 40270 | O34: 48680 | P34: 60420 | Q34: 77160
B35: Insulation Workers, Mechanical (47-2132) | C35: 25640 | D35: 5.4000001 | E35: 30.55 | F35: 63540 | G35: 2.2 | H35: 18.97 | I35: 22.83 | J35: 27.52 | K35: 36.2 | L35: 45.25 | M35: 39450 | N35: 47480 | O35: 57250 | P35: 75300 | Q35: 94110
B36: Painters and Paperhangers (47-2140) | C36: 225700 | D36: 1.6 | E36: 25.82 | F36: 53700 | G36: 0.69999999 | H36: 17.63 | I36: 20.43 | J36: 23.39 | K36: 28.97 | L36: 36.8 | M36: 36680 | N36: 42480 | O36: 48660 | P36: 60270 | Q36: 76540
A37: Painting | B37: Painters, Construction and Maintenance (47-2141) | C37: 224180 | D37: 1.6 | E37: 25.82 | F37: 53710 | G37: 0.69999999 | H37: 17.63 | I37: 20.44 | J37: 23.4 | K37: 28.97 | L37: 36.8 | M37: 36680 | N37: 42510 | O37: 48660 | P37: 60270 | Q37: 76550
B38: Paperhangers (47-2142) | C38: 1520 | D38: 13.7 | E38: 24.95 | F38: 51900 | G38: 3.9000001 | H38: 16.84 | I38: 19.68 | J38: 23.2 | K38: 28.11 | L38: 33.4 | M38: 35020 | N38: 40930 | O38: 48260 | P38: 58470 | Q38: 69470
B39: Pipelayers, Plumbers, Pipefitters, and Steamfitters (47-2150) | C39: 489520 | D39: 1.1 | E39: 33.11 | F39: 68870 | G39: 0.60000002 | H39: 19.17 | I39: 23.25 | J39: 29.91 | K39: 38.88 | L39: 50.03 | M39: 39880 | N39: 48360 | O39: 62210 | P39: 80880 | Q39: 104050
B40: Pipelayers (47-2151) | C40: 33580 | D40: 3.9000001 | E40: 26.09 | F40: 54270 | G40: 1.3 | H40: 17.71 | I40: 20.35 | J40: 23.42 | K40: 29.32 | L40: 38.81 | M40: 36840 | N40: 42320 | O40: 48710 | P40: 60980 | Q40: 80710
A41: Plumbing Rough In Plumbing Finishing | B41: Plumbers, Pipefitters, and Steamfitters (47-2152) | C41: 455940 | D41: 1.2 | E41: 33.63 | F41: 69940 | G41: 0.60000002 | H41: 19.55 | I41: 23.49 | J41: 30.27 | K41: 39.37 | L41: 50.55 | M41: 40670 | N41: 48860 | O41: 62970 | P41: 81900 | Q41: 105150
A42: Exterior Wall Finishing | B42: Plasterers and Stucco Masons (47-2161) | C42: 20880 | D42: 5.1999998 | E42: 29.33 | F42: 61000 | G42: 1.6 | H42: 18.56 | I42: 22.59 | J42: 26.93 | K42: 34.72 | L42: 44.68 | M42: 38610 | N42: 46990 | O42: 56020 | P42: 72210 | Q42: 92930
...

Sheet OEWS - California May 2024
B1: Multiple occupations for one geographical area
B3: Area: California
B4: Period: May 2024
A6: Capstone Construction Process Cat. | B6: Occupation (SOC code) | C6: Employment (1) | D6: Employment percent relative standard error (3) | E6: Hourly mean wage | F6: Annual mean wage (2) | G6: Wage percent relative standard error (3) | H6: Hourly 10th percentile wage | I6: Hourly 25th percentile wage | J6: Hourly median wage | K6: Hourly 75th percentile wage | L6: Hourly 90th percentile wage | M6: Annual 10th percentile wage (2) | N6: Annual 25th percentile wage (2) | O6: Annual median wage (2) | P6: Annual 75th percentile wage (2) | Q6: Annual 90th percentile wage (2) | R6: Employment per 1,000 jobs | S6: Location Quotient
B7: Construction and Extraction Occupations (47-0000) | C7: 679190 | D7: 0.69999999 | E7: 37.46 | F7: 77920 | G7: 0.69999999 | H7: 21.92 | I7: 25.96 | J7: 34.23 | K7: 46.23 | L7: 60.03 | M7: 45590 | N7: 53990 | O7: 71200 | P7: 96170 | Q7: 124870 | R7: 37.612 | S7: 0.91000003
B8: First-Line Supervisors of Construction Trades and Extraction Workers (47-1011) | C8: 72660 | D8: 2.2 | E8: 49.04 | F8: 101990 | G8: 0.89999998 | H8: 29.11 | I8: 36.73 | J8: 46.67 | K8: 60.31 | L8: 73.96 | M8: 60540 | N8: 76390 | O8: 97080 | P8: 125450 | Q8: 153830 | R8: 4.0240002 | S8: 0.76999998
B9: Boilermakers (47-2011) | C9: 690 | D9: 28.1 | E9: 52.12 | F9: 108420 | G9: 2.5999999 | H9: 35.91 | I9: 51.66 | J9: 51.73 | K9: 58.77 | L9: 61.07 | M9: 74690 | N9: 107450 | O9: 107600 | P9: 122240 | Q9: 127020 | R9: 0.037999999 | S9: 0.57999998
B10: Brickmasons and Blockmasons (47-2021) | C10: 3480 | D10: 18.700001 | E10: 34.81 | F10: 72410 | G10: 4.6999998 | H10: 23.06 | I10: 27 | J10: 31.93 | K10: 39.02 | L10: 51.68 | M10: 47950 | N10: 56160 | O10: 66420 | P10: 81170 | Q10: 107490 | R10: 0.192 | S10: 0.55000001
B11: Stonemasons (47-2022) | C11: 790 | D11: 23.700001 | E11: 31.78 | F11: 66110 | G11: 3.5 | H11: 22.78 | I11: 25.21 | J11: 31.19 | K11: 35.86 | L11: 39.56 | M11: 47370 | N11: 52430 | O11: 64880 | P11: 74590 | Q11: 82280 | R11: 0.044 | S11: 0.77999997
A12: Interior Wall framing Interior Wall sheathing Exterior Walls framing Exterior Wall sheathing Carpentry | B12: Carpenters (47-2031) | C12: 106500 | D12: 3.4000001 | E12: 37.35 | F12: 77680 | G12: 1.4 | H12: 22.68 | I12: 27.84 | J12: 35.97 | K12: 45.85 | L12: 57.3 | M12: 47170 | N12: 57900 | O12: 74820 | P12: 95360 | Q12: 119190 | R12: 5.8979998 | S12: 1.3
B13: Carpet Installers (47-2041) | C13: 2600 | D13: 19 | E13: 26.58 | F13: 55280 | G13: 3.9000001 | H13: 17.04 | I13: 17.94 | J13: 26.36 | K13: 31.44 | L13: 37.77 | M13: 35430 | N13: 37320 | O13: 54840 | P13: 65390 | Q13: 78560 | R13: 0.14399999 | S13: 1.48
A14: Floor framing Floor sheathing | B14: Floor Layers, Except Carpet, Wood, and Hard Tiles (47-2042) | C14: 6360 | D14: 11.8 | E14: 34.68 | F14: 72130 | G14: 4 | H14: 19.26 | I14: 24.15 | J14: 29.22 | K14: 46.49 | L14: 57.16 | M14: 40070 | N14: 50220 | O14: 60780 | P14: 96690 | Q14: 118900 | R14: 0.352 | S14: 2.1800001
B15: Floor Sanders and Finishers (47-2043) | C15: (8) - | D15: (8) - | E15: 28.27 | F15: 58800 | G15: 20.4 | H15: 19.1 | I15: 19.18 | J15: 21.72 | K15: 37.98 | L15: 40.73 | M15: 39730 | N15: 39900 | O15: 45180 | P15: 78990 | Q15: 84730 | R15: (8) - | S15: (8) -
A16: Floor Finishing | B16: Tile and Stone Setters (47-2044) | C16: 7250 | D16: 7.1999998 | E16: 29.12 | F16: 60580 | G16: 2.4000001 | H16: 19 | I16: 22.92 | J16: 27.65 | K16: 32.32 | L16: 38.71 | M16: 39530 | N16: 47670 | O16: 57510 | P16: 67220 | Q16: 80510 | R16: 0.40099999 | S16: 1.6
B17: Cement Masons and Concrete Finishers (47-2051) | C17: 29030 | D17: 5.1999998 | E17: 34.82 | F17: 72430 | G17: 1.7 | H17: 21.82 | I17: 24.95 | J17: 30.9 | K17: 42.51 | L17: 48.6 | M17: 45380 | N17: 51890 | O17: 64280 | P17: 88420 | Q17: 101090 | R17: 1.608 | S17: 1.21
B18: Terrazzo Workers and Finishers (47-2053) | C18: 220 | D18: 30.799999 | E18: 20.19 | F18: 42000 | G18: 1.5 | H18: 16.7 | I18: 16.97 | J18: 19.39 | K18: 22.57 | L18: 23.46 | M18: 34740 | N18: 35290 | O18: 40330 | P18: 46940 | Q18: 48790 | R18: 0.012 | S18: 1.3200001
A19: Site Work Foundations Assembly | B19: Construction Laborers (47-2061) | C19: 85370 | D19: 3.0999999 | E19: 31.8 | F19: 66140 | G19: 1.2 | H19: 20.39 | I19: 23.01 | J19: 29.11 | K19: 37.88 | L19: 45.29 | M19: 42410 | N19: 47850 | O19: 60540 | P19: 78790 | Q19: 94200 | R19: 4.7270002 | S19: 0.69
B20: Paving, Surfacing, and Tamping Equipment Operators (47-2071) | C20: 1920 | D20: 10.4 | E20: 43.28 | F20: 90010 | G20: 3.7 | H20: 24.78 | I20: 29.19 | J20: 38.2 | K20: 59.36 | L20: 63.58 | M20: 51540 | N20: 60720 | O20: 79460 | P20: 123470 | Q20: 132240 | R20: 0.106 | S20: 0.36000001
B21: Pile Driver Operators (47-2072) | C21: 790 | D21: 30.9 | E21: 50.83 | F21: 105720 | G21: 4.3000002 | H21: 32.7 | I21: 42.56 | J21: 50.94 | K21: 59.32 | L21: 64.01 | M21: 68010 | N21: 88520 | O21: 105950 | P21: 123380 | Q21: 133140 | R21: 0.044 | S21: 2.22
B22: Operating Engineers and Other Construction Equipment Operators (47-2073) | C22: 36040 | D22: 3.4000001 | E22: 45.04 | F22: 93680 | G22: 1.2 | H22: 26.31 | I22: 31.66 | J22: 42.85 | K22: 58.93 | L22: 63.08 | M22: 54730 | N22: 65840 | O22: 89120 | P22: 122570 | Q22: 131200 | R22: 1.9960001 | S22: 0.66000003
A23: Drywall | B23: Drywall and Ceiling Tile Installers (47-2081) | C23: 27350 | D23: 4.3000002 | E23: 36.64 | F23: 76210 | G23: 1.8 | H23: 22.09 | I23: 27.9 | J23: 31.67 | K23: 44.96 | L23: 58.72 | M23: 45950 | N23: 58020 | O23: 65880 | P23: 93520 | Q23: 122130 | R23: 1.515 | S23: 2.8199999
B24: Tapers (47-2082) | C24: 3790 | D24: 10 | E24: 35.73 | F24: 74310 | G24: 3.5 | H24: 21.49 | I24: 28.22 | J24: 33.49 | K24: 39.24 | L24: 53.39 | M24: 44690 | N24: 58700 | O24: 69670 | P24: 81630 | Q24: 111040 | R24: 0.20999999 | S24: 2.5899999
A25: Electrical Rough in Electrical Finishing | B25: Electricians (47-2111) | C25: 73420 | D25: 3 | E25: 41.24 | F25: 85780 | G25: 2.0999999 | H25: 22.42 | I25: 28.57 | J25: 36.8 | K25: 49.87 | L25: 65.73 | M25: 46630 | N25: 59420 | O25: 76540 | P25: 103720 | Q25: 136710 | R25: 4.066 | S25: 0.83999997
B26: Glaziers (47-2121) | C26: 7880 | D26: 9.6000004 | E26: 36.53 | F26: 75980 | G26: 3.7 | H26: 23 | I26: 27.86 | J26: 31.66 | K26: 48.33 | L26: 57.16 | M26: 47840 | N26: 57940 | O26: 65850 | P26: 100520 | Q26: 118880 | R26: 0.43599999 | S26: 1.1799999
A27: Insulation | B27: Insulation Workers, Floor, Ceiling, and Wall (47-2131) | C27: 2190 | D27: 14.1 | E27: 24.74 | F27: 51450 | G27: 4.3000002 | H27: 17.77 | I27: 18.47 | J27: 21.45 | K27: 27.59 | L27: 37.7 | M27: 36960 | N27: 38420 | O27: 44620 | P27: 57390 | Q27: 78420 | R27: 0.121 | S27: 0.47999999
B28: Insulation Workers, Mechanical (47-2132) | C28: 1260 | D28: 37.700001 | E28: 55.23 | F28: 114870 | G28: 13.1 | H28: 23.35 | I28: 35.42 | J28: 57.64 | K28: 74.55 | L28: 84.95 | M28: 48570 | N28: 73680 | O28: 119890 | P28: 155060 | Q28: 176690 | R28: 0.07 | S28: 0.41999999
A29: Painting | B29: Painters, Construction and Maintenance (47-2141) | C29: 37780 | D29: 3 | E29: 29.36 | F29: 61070 | G29: 1.5 | H29: 20.3 | I29: 22.95 | J29: 27.62 | K29: 32.89 | L29: 43.21 | M29: 42230 | N29: 47730 | O29: 57450 | P29: 68410 | Q29: 89870 | R29: 2.092 | S29: 1.4400001
B30: Paperhangers (47-2142) | C30: (8) - | D30: (8) - | E30: 31.46 | F30: 65440 | G30: 10.1 | H30: 20.47 | I30: 23.2 | J30: 27.56 | K30: 36.54 | L30: 51.48 | M30: 42570 | N30: 48260 | O30: 57330 | P30: 75990 | Q30: 107090 | R30: (8) - | S30: (8) -
B31: Pipelayers (47-2151) | C31: 1720 | D31: 23.299999 | E31: 37.02 | F31: 77000 | G31: 5.6999998 | H31: 22.8 | I31: 27.02 | J31: 37.54 | K31: 47.49 | L31: 54.34 | M31: 47420 | N31: 56200 | O31: 78090 | P31: 98770 | Q31: 113030 | R31: 0.094999999 | S31: 0.44
A32: Plumbing Rough In Plumbing Finishing | B32: Plumbers, Pipefitters, and Steamfitters (47-2152) | C32: 45460 | D32: 5.4000001 | E32: 37.67 | F32: 78350 | G32: 2 | H32: 21.87 | I32: 27.45 | J32: 32.88 | K32: 45.83 | L32: 60.96 | M32: 45480 | N32: 57090 | O32: 68390 | P32: 95320 | Q32: 126790 | R32: 2.517 | S32: 0.85000002
A33: Exterior Wall Finishing | B33: Plasterers and Stucco Masons (47-2161) | C33: 8370 | D33: 9.1999998 | E33: 31.08 | F33: 64640 | G33: 2.5999999 | H33: 20.09 | I33: 23.38 | J33: 29.03 | K33: 36.46 | L33: 47.22 | M33: 41790 | N33: 48630 | O33: 60370 | P33: 75840 | Q33: 98220 | R33: 0.46399999 | S33: 3.4200001
B34: Reinforcing Iron and Rebar Workers (47-2171) | C34: 1660 | D34: 19.6 | E34: 32.96 | F34: 68560 | G34: 5.8000002 | H34: 21.27 | I34: 23.66 | J34: 29.54 | K34: 45.02 | L34: 48.4 | M34: 44240 | N34: 49210 | O34: 61440 | P34: 93630 | Q34: 100660 | R34: 0.092 | S34: 1
A35: Roof framing Roof sheathing and waterproofing Exterior Roof Finishing | B35: Roofers (47-2181) | C35: 21110 | D35: 3.9000001 | E35: 32.73 | F35: 68080 | G35: 2.7 | H35: 22.64 | I35: 28.2 | J35: 30.31 | K35: 36.79 | L35: 45.71 | M35: 47090 | N35: 58650 | O35: 63040 | P35: 76520 | Q35: 95080 | R35: 1.169 | S35: 1.3200001
B36: Sheet Metal Workers (47-2211) | C36: 9180 | D36: 10.1 | E36: 41.6 | F36: 86530 | G36: 2.0999999 | H36: 22.5 | I36: 28.72 | J36: 38.28 | K36: 51.75 | L36: 63.57 | M36: 46800 | N36: 59730 | O36: 79630 | P36: 107640 | Q36: 132220 | R36: 0.50800002 | S36: 0.67000002
B37: Structural Iron and Steel Workers (47-2221) | C37: 6970 | D37: 11.7 | E37: 36.37 | F37: 75650 | G37: 4.3000002 | H37: 22.16 | I37: 23.79 | J37: 34.64 | K37: 48.86 | L37: 52.17 | M37: 46100 | N37: 49480 | O37: 72050 | P37: 101640 | Q37: 108510 | R37: 0.38600001 | S37: 0.92000002
B38: Solar Photovoltaic Installers (47-2231) | C38: 8970 | D38: 12.8 | E38: 31.94 | F38: 66440 | G38: 2.4000001 | H38: 23.1 | I38: 25.73 | J38: 29.23 | K38: 37.12 | L38: 45.62 | M38: 48050 | N38: 53510 | O38: 60790 | P38: 77220 | Q38: 94890 | R38: 0.49599999 | S38: 2.71
B39: Helpers--Brickmasons, Blockmasons, Stonemasons, and Tile and Marble Setters (47-3011) | C39: 3900 | D39: 11.2 | E39: 26.36 | F39: 54820 | G39: 2.2 | H39: 18.24 | I39: 21.87 | J39: 24.87 | K39: 29.74 | L39: 35.8 | M39: 37930 | N39: 45480 | O39: 51720 | P39: 61860 | Q39: 74460 | R39: 0.21600001 | S39: 2.1300001
B40: Helpers--Carpenters (47-3012) | C40: 2250 | D40: 24.4 | E40: 24.49 | F40: 50940 | G40: 3.7 | H40: 17.77 | I40: 20.55 | J40: 22 | K40: 25.34 | L40: 40.8 | M40: 36950 | N40: 42740 | O40: 45760 | P40: 52710 | Q40: 84860 | R40: 0.124 | S40: 0.77999997
B41: Helpers--Electricians (47-3013) | C41: 1790 | D41: 38.700001 | E41: 25.36 | F41: 52760 | G41: 10.3 | H41: 17.79 | I41: 18.58 | J41: 22.86 | K41: 28.34 | L41: 38.66 | M41: 36990 | N41: 38650 | O41: 47540 | P41: 58940 | Q41: 80410 | R41: 0.098999999 | S41: 0.23999999
B42: Helpers--Painters, Paperhangers, Plasterers, and Stucco Masons (47-3014) | C42: 1920 | D42: 16.1 | E42: 23.32 | F42: 48510 | G42: 2.3 | H42: 18.06 | I42: 19 | J42: 21.99 | K42: 24.39 | L42: 27.9 | M42: 37570 | N42: 39520 | O42: 45730 | P42: 50730 | Q42: 58040 | R42: 0.106 | S42: 2.27
...

Sheet OEWS - Utah May 2024
B1: Multiple occupations for one geographical area
B3: Area: Utah
B4: Period: May 2024
A6: Capstone Construction Process Cat. | B6: Occupation (SOC code) | C6: Employment (1) | D6: Employment percent relative standard error (3) | E6: Hourly mean wage | F6: Annual mean wage (2) | G6: Wage percent relative standard error (3) | H6: Hourly 10th percentile wage | I6: Hourly 25th percentile wage | J6: Hourly median wage | K6: Hourly 75th percentile wage | L6: Hourly 90th percentile wage | M6: Annual 10th percentile wage (2) | N6: Annual 25th percentile wage (2) | O6: Annual median wage (2) | P6: Annual 75th percentile wage (2) | Q6: Annual 90th percentile wage (2) | R6: Employment per 1,000 jobs | S6: Location Quotient
B7: Construction and Extraction Occupations (47-0000) | C7: 111490 | D7: 1.6 | E7: 27.78 | F7: 57770 | G7: 0.69999999 | H7: 17.87 | I7: 21.94 | J7: 25.85 | K7: 31.94 | L7: 38.88 | M7: 37170 | N7: 45630 | O7: 53780 | P7: 66430 | Q7: 80860 | R7: 65.208 | S7: 1.58
B8: First-Line Supervisors of Construction Trades and Extraction Workers (47-1011) | C8: 13250 | D8: 3.3 | E8: 38.09 | F8: 79230 | G8: 1.1 | H8: 24.97 | I8: 29.85 | J8: 36.58 | K8: 44.99 | L8: 53.69 | M8: 51940 | N8: 62080 | O8: 76080 | P8: 93580 | Q8: 111680 | R8: 7.7490001 | S8: 1.48
B9: Brickmasons and Blockmasons (47-2021) | C9: 1810 | D9: 18.1 | E9: 27.69 | F9: 57590 | G9: 3.0999999 | H9: 18.84 | I9: 23.31 | J9: 27.09 | K9: 31.8 | L9: 35.56 | M9: 39180 | N9: 48480 | O9: 56340 | P9: 66150 | Q9: 73960 | R9: 1.059 | S9: 3.05
B10: Stonemasons (47-2022) | C10: 330 | D10: 35.700001 | E10: 26.8 | F10: 55750 | G10: 7.6999998 | H10: 17.5 | I10: 19.05 | J10: 24.34 | K10: 28.27 | L10: 38.92 | M10: 36400 | N10: 39620 | O10: 50630 | P10: 58800 | Q10: 80950 | R10: 0.192 | S10: 3.3800001
A11: Interior Wall framing Interior Wall sheathing Exterior Walls framing Exterior Wall sheathing Carpentry | B11: Carpenters (47-2031) | C11: 14040 | D11: 5.8000002 | E11: 26.26 | F11: 54620 | G11: 1.3 | H11: 18.37 | I11: 21.85 | J11: 24.86 | K11: 29.67 | L11: 35.66 | M11: 38200 | N11: 45450 | O11: 51720 | P11: 61720 | Q11: 74180 | R11: 8.2119999 | S11: 1.8099999
B12: Carpet Installers (47-2041) | C12: 350 | D12: 23.799999 | E12: 21.13 | F12: 43950 | G12: 8.8999996 | H12: 14.81 | I12: 17.08 | J12: 20.81 | K12: 23.07 | L12: 30.06 | M12: 30810 | N12: 35520 | O12: 43270 | P12: 47990 | Q12: 62530 | R12: 0.207 | S12: 2.1300001
A13: Floor framing Floor sheathing | B13: Floor Layers, Except Carpet, Wood, and Hard Tiles (47-2042) | C13: 260 | D13: 30 | E13: 22.81 | F13: 47450 | G13: 7.5 | H13: 15.25 | I13: 17.04 | J13: 21.12 | K13: 25.08 | L13: 35.32 | M13: 31730 | N13: 35450 | O13: 43930 | P13: 52170 | Q13: 73470 | R13: 0.152 | S13: 0.94
A14: Floor Finishing | B14: Tile and Stone Setters (47-2044) | C14: 1950 | D14: 11.3 | E14: 24.67 | F14: 51320 | G14: 4.4000001 | H14: 14.95 | I14: 18.47 | J14: 23.46 | K14: 29 | L14: 36.68 | M14: 31100 | N14: 38410 | O14: 48790 | P14: 60320 | Q14: 76280 | R14: 1.138 | S14: 4.5300002
B15: Cement Masons and Concrete Finishers (47-2051) | C15: 5700 | D15: 9.1000004 | E15: 26.49 | F15: 55100 | G15: 1.4 | H15: 21.57 | I15: 22.74 | J15: 26.7 | K15: 29.64 | L15: 31.81 | M15: 44860 | N15: 47290 | O15: 55540 | P15: 61650 | Q15: 66160 | R15: 3.3329999 | S15: 2.5
A16: Site Work Foundations Assembly | B16: Construction Laborers (47-2061) | C16: 22230 | D16: 6.6999998 | E16: 22.96 | F16: 47750 | G16: 2 | H16: 15.68 | I16: 18.25 | J16: 22.16 | K16: 24.84 | L16: 30.69 | M16: 32610 | N16: 37960 | O16: 46100 | P16: 51660 | Q16: 63840 | R16: 12.999 | S16: 1.9
B17: Paving, Surfacing, and Tamping Equipment Operators (47-2071) | C17: 540 | D17: 30.6 | E17: 25.63 | F17: 53320 | G17: 3.7 | H17: 20.72 | I17: 21.53 | J17: 23.02 | K17: 30.01 | L17: 33.78 | M17: 43110 | N17: 44780 | O17: 47890 | P17: 62420 | Q17: 70270 | R17: 0.317 | S17: 1.0700001
B18: Operating Engineers and Other Construction Equipment Operators (47-2073) | C18: 6320 | D18: 4.3000002 | E18: 28.28 | F18: 58820 | G18: 0.89999998 | H18: 21.94 | I18: 24.17 | J18: 28.73 | K18: 30.69 | L18: 35.21 | M18: 45630 | N18: 50270 | O18: 59760 | P18: 63840 | Q18: 73240 | R18: 3.6949999 | S18: 1.21
A19: Drywall | B19: Drywall and Ceiling Tile Installers (47-2081) | C19: 1830 | D19: 12.7 | E19: 24.65 | F19: 51270 | G19: 2.0999999 | H19: 17.24 | I19: 19 | J19: 24.45 | K19: 28.43 | L19: 33 | M19: 35850 | N19: 39520 | O19: 50860 | P19: 59140 | Q19: 68630 | R19: 1.0700001 | S19: 1.99
B20: Tapers (47-2082) | C20: 400 | D20: 25.9 | E20: 25.91 | F20: 53880 | G20: 4.5999999 | H20: 17.12 | I20: 19.26 | J20: 26.24 | K20: 29.39 | L20: 36.32 | M20: 35600 | N20: 40060 | O20: 54580 | P20: 61120 | Q20: 75540 | R20: 0.234 | S20: 2.8800001
A21: Electrical Rough in Electrical Finishing | B21: Electricians (47-2111) | C21: 11360 | D21: 6.0999999 | E21: 30.3 | F21: 63010 | G21: 1.7 | H21: 18.38 | I21: 22.94 | J21: 29.53 | K21: 37.5 | L21: 39.62 | M21: 38230 | N21: 47720 | O21: 61430 | P21: 78000 | Q21: 82410 | R21: 6.6430001 | S21: 1.38
B22: Glaziers (47-2121) | C22: 740 | D22: 22.6 | E22: 26.31 | F22: 54720 | G22: 3.5999999 | H22: 20.44 | I22: 22.62 | J22: 24.35 | K22: 28.86 | L22: 31.61 | M22: 42510 | N22: 47050 | O22: 50640 | P22: 60030 | Q22: 65750 | R22: 0.43099999 | S22: 1.16
A23: Insulation | B23: Insulation Workers, Floor, Ceiling, and Wall (47-2131) | C23: 350 | D23: 29.4 | E23: 22.48 | F23: 46760 | G23: 1.9 | H23: 18.14 | I23: 19.05 | J23: 23.23 | K23: 24.44 | L23: 27.35 | M23: 37740 | N23: 39620 | O23: 48330 | P23: 50830 | Q23: 56880 | R23: 0.205 | S23: 0.81999999
B24: Insulation Workers, Mechanical (47-2132) | C24: 350 | D24: 25 | E24: 23.24 | F24: 48340 | G24: 7.1999998 | H24: 16.94 | I24: 20.39 | J24: 22.02 | K24: 28.03 | L24: 29.48 | M24: 35230 | N24: 42420 | O24: 45800 | P24: 58300 | Q24: 61320 | R24: 0.20299999 | S24: 1.22
A25: Painting | B25: Painters, Construction and Maintenance (47-2141) | C25: 3350 | D25: 5.6999998 | E25: 22.24 | F25: 46270 | G25: 1.6 | H25: 17.37 | I25: 18.02 | J25: 22.07 | K25: 23.82 | L25: 28.74 | M25: 36130 | N25: 37480 | O25: 45900 | P25: 49540 | Q25: 59780 | R25: 1.957 | S25: 1.35
B26: Pipelayers (47-2151) | C26: 710 | D26: 18.799999 | E26: 25.43 | F26: 52890 | G26: 1 | H26: 23.01 | I26: 23.45 | J26: 24.61 | K26: 26.92 | L26: 28.94 | M26: 47860 | N26: 48780 | O26: 51180 | P26: 55990 | Q26: 60190 | R26: 0.41499999 | S26: 1.91
A27: Plumbing Rough In Plumbing Finishing | B27: Plumbers, Pipefitters, and Steamfitters (47-2152) | C27: 6770 | D27: 8 | E27: 30.1 | F27: 62600 | G27: 1.7 | H27: 19.12 | I27: 23.28 | J27: 29.65 | K27: 37 | L27: 39.16 | M27: 39770 | N27: 48410 | O27: 61680 | P27: 76970 | Q27: 81460 | R27: 3.9579999 | S27: 1.34
A28: Exterior Wall Finishing | B28: Plasterers and Stucco Masons (47-2161) | C28: 1200 | D28: 16.700001 | E28: 27.61 | F28: 57420 | G28: 5.0999999 | H28: 17.3 | I28: 23.03 | J28: 25.56 | K28: 34.23 | L28: 38.12 | M28: 35980 | N28: 47910 | O28: 53170 | P28: 71210 | Q28: 79280 | R28: 0.699 | S28: 5.1599998
B29: Reinforcing Iron and Rebar Workers (47-2171) | C29: 280 | D29: 35.200001 | E29: 24.64 | F29: 51240 | G29: 7.6999998 | H29: 20.66 | I29: 21.65 | J29: 24.04 | K29: 26.4 | L29: 30.23 | M29: 42970 | N29: 45030 | O29: 49990 | P29: 54900 | Q29: 62880 | R29: 0.16599999 | S29: 1.8099999
A30: Roof framing Roof sheathing and waterproofing Exterior Roof Finishing | B30: Roofers (47-2181) | C30: 2940 | D30: 7 | E30: 25.36 | F30: 52750 | G30: 2.7 | H30: 16.24 | I30: 21.78 | J30: 23.94 | K30: 30.09 | L30: 37.81 | M30: 33770 | N30: 45310 | O30: 49800 | P30: 62590 | Q30: 78640 | R30: 1.722 | S30: 1.9400001
B31: Sheet Metal Workers (47-2211) | C31: 1870 | D31: 17 | E31: 29.96 | F31: 62310 | G31: 3.0999999 | H31: 20.04 | I31: 23.25 | J31: 29.08 | K31: 36.66 | L31: 42.26 | M31: 41680 | N31: 48360 | O31: 60490 | P31: 76250 | Q31: 87900 | R31: 1.091 | S31: 1.4299999
B32: Structural Iron and Steel Workers (47-2221) | C32: 1200 | D32: 17.700001 | E32: 24.01 | F32: 49940 | G32: 5.1999998 | H32: 16.26 | I32: 18.34 | J32: 23 | K32: 30.82 | L32: 32.38 | M32: 33820 | N32: 38150 | O32: 47840 | P32: 64110 | Q32: 67350 | R32: 0.704 | S32: 1.6799999
B33: Solar Photovoltaic Installers (47-2231) | C33: 540 | D33: 21.299999 | E33: 25.86 | F33: 53790 | G33: 4.9000001 | H33: 17.65 | I33: 20 | J33: 23.06 | K33: 30.25 | L33: 37.31 | M33: 36710 | N33: 41600 | O33: 47960 | P33: 62920 | Q33: 77600 | R33: 0.31799999 | S33: 1.74
B34: Helpers--Brickmasons, Blockmasons, Stonemasons, and Tile and Marble Setters (47-3011) | C34: 380 | D34: 22.6 | E34: 23.21 | F34: 48290 | G34: 4.5999999 | H34: 17.89 | I34: 19.49 | J34: 23.12 | K34: 25.02 | L34: 31.17 | M34: 37220 | N34: 40550 | O34: 48090 | P34: 52050 | Q34: 64830 | R34: 0.223 | S34: 2.2
B35: Helpers--Carpenters (47-3012) | C35: 620 | D35: 47.799999 | E35: 20.58 | F35: 42800 | G35: 5.9000001 | H35: 14 | I35: 19.34 | J35: 20.72 | K35: 21.71 | L35: 25 | M35: 29130 | N35: 40240 | O35: 43090 | P35: 45160 | Q35: 52000 | R35: 0.36399999 | S35: 2.28
B36: Helpers--Electricians (47-3013) | C36: 310 | D36: 46.200001 | E36: 21.4 | F36: 44500 | G36: 8.8000002 | H36: 18.08 | I36: 19.18 | J36: 20.25 | K36: 24.01 | L36: 29.83 | M36: 37610 | N36: 39880 | O36: 42120 | P36: 49940 | Q36: 62050 | R36: 0.17900001 | S36: 0.43000001
B37: Helpers--Painters, Paperhangers, Plasterers, and Stucco Masons (47-3014) | C37: 150 | D37: 32.400002 | E37: 19.61 | F37: 40780 | G37: 1 | H37: 16.7 | I37: 17 | J37: 19.53 | K37: 20.47 | L37: 21.18 | M37: 34730 | N37: 35360 | O37: 40620 | P37: 42570 | Q37: 44050 | R37: 0.089000002 | S37: 1.9
B38: Helpers--Pipelayers, Plumbers, Pipefitters, and Steamfitters (47-3015) | C38: 240 | D38: 33.200001 | E38: 20.43 | F38: 42500 | G38: 6.0999999 | H38: 13.15 | I38: 14.13 | J38: 21.55 | K38: 23.84 | L38: 26.2 | M38: 27360 | N38: 29390 | O38: 44810 | P38: 49580 | Q38: 54500 | R38: 0.141 | S38: 0.5
B39: Helpers, Construction Trades, All Other (47-3019) | C39: 230 | D39: 24.6 | E39: 18.83 | F39: 39170 | G39: 6.5999999 | H39: 11 | I39: 15.41 | J39: 17.54 | K39: 24.04 | L39: 25.22 | M39: 22890 | N39: 32060 | O39: 36490 | P39: 49990 | Q39: 52460 | R39: 0.13600001 | S39: 0.81999999
A40: All Inspections | B40: Construction and Building Inspectors (47-4011) | C40: 1260 | D40: 8.3999996 | E40: 34.32 | F40: 71390 | G40: 1.8 | H40: 20.88 | I40: 27.06 | J40: 34.15 | K40: 40.37 | L40: 48.11 | M40: 43420 | N40: 56280 | O40: 71040 | P40: 83970 | Q40: 100070 | R40: 0.73900002 | S40: 0.82999998
A41: Mechanical Rough In Mechanical Finishing | B41: Installation, Maintenance, and Repair Occupations (49-0000) | C41: 66680 | D41: 1.5 | E41: 28.5 | F41: 59270 | G41: 0.60000002 | H41: 17.06 | I41: 21.31 | J41: 27.46 | K41: 34.63 | L41: 41.03 | M41: 35490 | N41: 44320 | O41: 57110 | P41: 72040 | Q41: 85350 | R41: 38.998001 | S41: 0.99000001
B42: First-Line Supervisors of Mechanics, Installers, and Repairers (49-1011) | C42: 6410 | D42: 3.9000001 | E42: 38.77 | F42: 80650 | G42: 1.2 | H42: 23.18 | I42: 29 | J42: 37.2 | K42: 46.69 | L42: 58.28 | M42: 48210 | N42: 60320 | O42: 77380 | P42: 97120 | Q42: 121220 | R42: 3.75 | S42: 0.95999998
...

Sheet Process Lookup
A1: Select a Process | C1: Configuration | D1: Process Cost | E1: Process Profit | F1: Process Selling Price | G1: Profit Margin of Process | I1: Unit of measure | K1: Notes
A2: Site Work | C2: LA - Site Built | D2: {=_xlfn.XLOOKUP( $A$2, INDIRECT("'" & C2 & "'!A:A"), INDIRECT( "'" & C2 & "'!" & IF(ISNUMBER(SEARCH("Local",C2)),"F","G") & ":" & IF(ISNUMBER(SEARCH("Local",C2)),"F","G") ) )} -> 24.32 | E2: {=_xlfn.XLOOKUP( $A$2, INDIRECT("'" & $C2 & "'!A:A"), INDIRECT( "'" & $C2 & "'!" & IF(ISNUMBER(SEARCH("Local",$C2)),"E","F") & ":" & IF(ISNUMBER(SEARCH("Local",$C2)),"E","F") ) )*INDIRECT("'" & $C2 & "'!C41")} -> 3.0064626 | F2: =E2+D2 -> 27.326463 | G2: =E2/F2 -> 0.11002019 | I2: ='Parameter Adjustment'!Z2 -> Square foot | K2: *Go to parameter adjustment page to move
C3: LA - Local | D3: {=_xlfn.XLOOKUP( $A$2, INDIRECT("'" & C3 & "'!A:A"), INDIRECT( "'" & C3 & "'!" & IF(ISNUMBER(SEARCH("Local",C3)),"F","G") & ":" & IF(ISNUMBER(SEARCH("Local",C3)),"F","G") ) )} -> 24.32 | E3: {=_xlfn.XLOOKUP( $A$2, INDIRECT("'" & $C3 & "'!A:A"), INDIRECT( "'" & $C3 & "'!" & IF(ISNUMBER(SEARCH("Local",$C3)),"E","F") & ":" & IF(ISNUMBER(SEARCH("Local",$C3)),"E","F") ) )*INDIRECT("'" & $C3 & "'!C41")} -> #VALUE! | F3: =E3+D3 -> #VALUE! | G3: =E3/F3 -> #VALUE!
C4: SLC - Site Built | D4: {=_xlfn.XLOOKUP( $A$2, INDIRECT("'" & C4 & "'!A:A"), INDIRECT( "'" & C4 & "'!" & IF(ISNUMBER(SEARCH("Local",C4)),"F","G") & ":" & IF(ISNUMBER(SEARCH("Local",C4)),"F","G") ) )} -> 11.4 | E4: {=_xlfn.XLOOKUP( $A$2, INDIRECT("'" & $C4 & "'!A:A"), INDIRECT( "'" & $C4 & "'!" & IF(ISNUMBER(SEARCH("Local",$C4)),"E","F") & ":" & IF(ISNUMBER(SEARCH("Local",$C4)),"E","F") ) )*INDIRECT("'" & $C4 & "'!C41")} -> 1.4092793 | F4: =E4+D4 -> 12.809279 | G4: =E4/F4 -> 0.11002019
C5: SLC - Local | D5: {=_xlfn.XLOOKUP( $A$2, INDIRECT("'" & C5 & "'!A:A"), INDIRECT( "'" & C5 & "'!" & IF(ISNUMBER(SEARCH("Local",C5)),"F","G") & ":" & IF(ISNUMBER(SEARCH("Local",C5)),"F","G") ) )} -> 11.4 | E5: {=_xlfn.XLOOKUP( $A$2, INDIRECT("'" & $C5 & "'!A:A"), INDIRECT( "'" & $C5 & "'!" & IF(ISNUMBER(SEARCH("Local",$C5)),"E","F") & ":" & IF(ISNUMBER(SEARCH("Local",$C5)),"E","F") ) )*INDIRECT("'" & $C5 & "'!C41")} -> 0.47104954 | F5: =E5+D5 -> 11.87105 | G5: =E5/F5 -> 0.03968053
C6: NA - Site Built | D6: {=_xlfn.XLOOKUP( $A$2, INDIRECT("'" & C6 & "'!A:A"), INDIRECT( "'" & C6 & "'!" & IF(ISNUMBER(SEARCH("Local",C6)),"F","G") & ":" & IF(ISNUMBER(SEARCH("Local",C6)),"F","G") ) )} -> 12.236 | E6: {=_xlfn.XLOOKUP( $A$2, INDIRECT("'" & $C6 & "'!A:A"), INDIRECT( "'" & $C6 & "'!" & IF(ISNUMBER(SEARCH("Local",$C6)),"E","F") & ":" & IF(ISNUMBER(SEARCH("Local",$C6)),"E","F") ) )*INDIRECT("'" & $C6 & "'!C41")} -> 1.5126265 | F6: =E6+D6 -> 13.748626 | G6: =E6/F6 -> 0.11002019
C7: NA - Local | D7: {=_xlfn.XLOOKUP( $A$2, INDIRECT("'" & C7 & "'!A:A"), INDIRECT( "'" & C7 & "'!" & IF(ISNUMBER(SEARCH("Local",C7)),"F","G") & ":" & IF(ISNUMBER(SEARCH("Local",C7)),"F","G") ) )} -> 12.236 | E7: {=_xlfn.XLOOKUP( $A$2, INDIRECT("'" & $C7 & "'!A:A"), INDIRECT( "'" & $C7 & "'!" & IF(ISNUMBER(SEARCH("Local",$C7)),"E","F") & ":" & IF(ISNUMBER(SEARCH("Local",$C7)),"E","F") ) )*INDIRECT("'" & $C7 & "'!C41")} -> #VALUE! | F7: =E7+D7 -> #VALUE! | G7: =E7/F7 -> #VALUE!

Sheet Detail Results
A1: Select a Scenario | C1: Process | D1: Cost | E1: Profit | F1: Selling Price | G1: Profit Margin | I1: Unit of measure* | K1: Notes
A2: SLC - Local | C2: Site Work | D2: {=INDIRECT("'" & $A$2 & "'!" & IF(ISNUMBER(SEARCH("Local",$A$2)),"F","G") & ROW()+1)} -> 11.4 | E2: {=_xlfn.XLOOKUP( C2, INDIRECT("'" & $A$2 & "'!A:A"), INDIRECT( "'" & $A$2 & "'!" & IF(ISNUMBER(SEARCH("Local",$A$2)),"E","F") & ":" & IF(ISNUMBER(SEARCH("Local",$A$2)),"E","F") ) )*INDIRECT("'" & $A$2 & "'!C41")} -> 0.47104954 | F2: =E2+D2 -> 11.87105 | G2: =IF(F2=0, "", E2/F2) -> 0.03968053 | I2: ='Parameter Adjustment'!Z2 -> Square foot | K2: *Go to parameter adjustment page to move
C3: Foundations | D3: {=INDIRECT("'" & $A$2 & "'!" & IF(ISNUMBER(SEARCH("Local",$A$2)),"F","G") & ROW()+1)} -> 15.75 | E3: {=_xlfn.XLOOKUP( C3, INDIRECT("'" & $A$2 & "'!A:A"), INDIRECT( "'" & $A$2 & "'!" & IF(ISNUMBER(SEARCH("Local",$A$2)),"E","F") & ":" & IF(ISNUMBER(SEARCH("Local",$A$2)),"E","F") ) )*INDIRECT("'" & $A$2 & "'!C41")} -> 0.75925748 | F3: =E3+D3 -> 16.509257 | G3: =IF(F3=0, "", E3/F3) -> 0.045989802
C4: Floor framing | D4: {=INDIRECT("'" & $A$2 & "'!" & IF(ISNUMBER(SEARCH("Local",$A$2)),"F","G") & ROW()+1)} -> 2.80125 | E4: {=_xlfn.XLOOKUP( C4, INDIRECT("'" & $A$2 & "'!A:A"), INDIRECT( "'" & $A$2 & "'!" & IF(ISNUMBER(SEARCH("Local",$A$2)),"E","F") & ":" & IF(ISNUMBER(SEARCH("Local",$A$2)),"E","F") ) )*INDIRECT("'" & $A$2 & "'!C41")} -> 0.11574803 | F4: =E4+D4 -> 2.916998 | G4: =IF(F4=0, "", E4/F4) -> 0.03968053
